[2016-10-07 14:52:20,018: WARNING/MainProcess] /vagrant/final_project/.env/lib/python3.5/site-packages/celery/fixups/django.py:265: UserWarning: Using settings.DEBUG leads to a memory leak, never use this setting in production environments!
  warnings.warn('Using settings.DEBUG leads to a memory leak, never '
[2016-10-07 14:52:20,020: WARNING/MainProcess] celery@precise64 ready.
[2016-10-07 14:52:20,025: ERROR/MainProcess] Received unregistered task of type 'tasks.mail'.
The message has been ignored and discarded.

Did you remember to import the module containing this task?
Or maybe you are using relative imports?
Please see http://bit.ly/gLye1c for more information.

The full contents of the message body was:
{'timelimit': [None, None], 'task': 'tasks.mail', 'eta': None, 'utc': True, 'args': [], 'kwargs': {}, 'callbacks': None, 'expires': None, 'errbacks': None, 'retries': 0, 'id': '2903273d-daa3-435a-9a05-bc8f43c6bb77', 'chord': None, 'taskset': None} (247b)
Traceback (most recent call last):
  File "/vagrant/final_project/.env/lib/python3.5/site-packages/celery/worker/consumer.py", line 465, in on_task_received
    strategies[type_](message, body,
KeyError: 'tasks.mail'
[2016-10-07 14:52:20,030: ERROR/MainProcess] Received unregistered task of type 'tasks.mail'.
The message has been ignored and discarded.

Did you remember to import the module containing this task?
Or maybe you are using relative imports?
Please see http://bit.ly/gLye1c for more information.

The full contents of the message body was:
{'timelimit': [None, None], 'task': 'tasks.mail', 'eta': None, 'utc': True, 'args': [], 'kwargs': {}, 'callbacks': None, 'expires': None, 'errbacks': None, 'retries': 0, 'id': 'a974cceb-01a1-4479-82c9-e2268edb1ff4', 'chord': None, 'taskset': None} (247b)
Traceback (most recent call last):
  File "/vagrant/final_project/.env/lib/python3.5/site-packages/celery/worker/consumer.py", line 465, in on_task_received
    strategies[type_](message, body,
KeyError: 'tasks.mail'
[2016-10-07 14:52:20,032: ERROR/MainProcess] Received unregistered task of type 'tasks.mail'.
The message has been ignored and discarded.

Did you remember to import the module containing this task?
Or maybe you are using relative imports?
Please see http://bit.ly/gLye1c for more information.

The full contents of the message body was:
{'timelimit': [None, None], 'task': 'tasks.mail', 'eta': None, 'utc': True, 'args': [], 'kwargs': {}, 'callbacks': None, 'expires': None, 'errbacks': None, 'retries': 0, 'id': 'd717d9d8-779f-4679-bd81-e26fa2951c3d', 'chord': None, 'taskset': None} (247b)
Traceback (most recent call last):
  File "/vagrant/final_project/.env/lib/python3.5/site-packages/celery/worker/consumer.py", line 465, in on_task_received
    strategies[type_](message, body,
KeyError: 'tasks.mail'
[2016-10-07 14:52:20,034: ERROR/MainProcess] Received unregistered task of type 'tasks.mail'.
The message has been ignored and discarded.

Did you remember to import the module containing this task?
Or maybe you are using relative imports?
Please see http://bit.ly/gLye1c for more information.

The full contents of the message body was:
{'timelimit': [None, None], 'task': 'tasks.mail', 'eta': None, 'utc': True, 'args': [], 'kwargs': {}, 'callbacks': None, 'expires': None, 'errbacks': None, 'retries': 0, 'id': '9d8b2bc8-8c6c-49b0-825c-a34c485643d1', 'chord': None, 'taskset': None} (247b)
Traceback (most recent call last):
  File "/vagrant/final_project/.env/lib/python3.5/site-packages/celery/worker/consumer.py", line 465, in on_task_received
    strategies[type_](message, body,
KeyError: 'tasks.mail'
